Workbook

Sheet 前提条件
A1: UNLID 財務モデル 前提条件 v4.7 ─ 単位：万円 | 中央値シナリオ
A2: v4.7変更：①元金返済Row30追加（据置12ヶ月・月33万×60回）、Row26更新／②法人税タイミング参照行(Row31)追加 ／③DSCR指標セクション追加（前提条件⑩）
A4: ① 売上ドライバー
A5: 項目 | B5: Year1 | C5: Year2 | D5: Year3
A6: B2B契約企業数（期末純増・社） | B6: 10 | C6: 50 | D6: 160
A7: FDE受託 月額単価（万円/社） | B7: =B93 | C7: =ROUND((B6*B93+(C6-B6)*C93)/C6,0) | D7: =ROUND((C6*C7+(D6-C6)*D93)/D6,0)
A8: B2B受託収益（万円） | B8: =(0+B6)/2*B7*12 | C8: =(B6+C6)/2*C7*12 | D8: =(C6+D6)/2*D7*12
A9: 人材紹介成立件数（件） | B9: 3 | C9: 20 | D9: 40
A10: 人材紹介フィー単価（万円/件） | B10: 140 | C10: 140 | D10: 140
A11: 人材紹介フィー合計（万円） | B11: =B9*B10 | C11: =C9*C10 | D11: =D9*D10
A12: 受託プロジェクト件数（件） | B12: 0 | C12: 5 | D12: 15
A13: プロジェクト単価（万円/件・ベース） | B13: 0 | C13: 160 | D13: 160
A14: プロジェクト収益（万円） | B14: =B12*B13 | C14: =C12*C13 | D14: =D12*D13
A15: 売上合計（万円） | B15: ='PL（損益計算書）'!B9 | C15: ='PL（損益計算書）'!C9 | D15: ='PL（損益計算書）'!D9
A16: ※ v4.3修正：B2Bは期中平均社数（（期首＋期末）÷2）×単価×12ヶ月で計算。Y1期首=0社前提。「純増」はChurn率2.0%（Y1/Y2）・1.5%（Y3）を織り込んだ後の純社数（詳細は⑦参照）
A17: ※ FDE月額単価上昇（20→23→25万円）は既存顧客への値上げではなく、新規顧客を上位プランで獲得する設計。既存契約は契約時単価で継続→Churn率への影響軽微。
A18: ② COGS（売上原価）前提 ─ サーバー/API費・外注費
A19: 項目 | B19: Year1 | C19: Year2 | D19: Year3
A20: AIサーバー・インフラ費（万円） | B20: 24 | C20: 72 | D20: 180
A21: 外部API利用料（OpenAI等・万円） | B21: 12 | C21: 60 | D21: 180
A22: 副業ワーカー報酬率（対B2B受託売上） | B22: 0.09 | C22: 0.08 | D22: 0.08
A23: 副業ワーカー報酬（万円） | B23: =B8*B22 | C23: =C8*C22 | D23: =D8*D22
A24: 外注エンジニア費（プロジェクト分・万円） | B24: 0 | C24: 200 | D24: 600
A25: COGS合計（万円） | B25: =SUM(B20:B24) | C25: =SUM(C20:C24) | D25: =SUM(D20:D24)
A26: 売上総利益（万円） | B26: =B15-B25 | C26: =C15-C25 | D26: =D15-D25
A27: 粗利率 | B27: =B26/B15 | C27: =C26/C15 | D27: =D26/D15
A29: ③ SG&A（販売費及び一般管理費）前提 ─ 人員計画シートと連動
A30: 項目 | B30: Year1 | C30: Year2 | D30: Year3
A31: 人件費合計（万円）※人員計画シート参照 | B31: =人員計画!D32 | C31: =人員計画!E32 | D31: =人員計画!F32
A32: 採用費合計（万円）※人員計画シート参照 | B32: =人員計画!D42 | C32: =人員計画!E42 | D32: =人員計画!F42
A33: B2Bマーケティング・CAC費（万円） | B33: 120 | C33: 360 | D33: 600
A34: 人材紹介 候補者集客広告費（万円） | B34: 30 | C34: 200 | D34: 500
A35: 地代家賃・オフィス費（万円） | B35: 60 | C35: 180 | D35: 360
A36: SaaSツール・システム費（万円） | B36: 60 | C36: 120 | D36: 240
A37: 法務・許認可・顧問費（万円） | B37: 200 | C37: 300 | D37: 400
A38: その他固定費（万円） | B38: 60 | C38: 120 | D38: 200
A39: SG&A合計（万円） | B39: =SUM(B31:B38) | C39: =SUM(C31:C38) | D39: =SUM(D31:D38)
A40: 営業利益（万円） | B40: =B26-B39 | C40: =C26-C39 | D40: =D26-D39
A41: 営業利益率 | B41: =B40/B15 | C41: =C40/C15 | D41: =D40/D15
A43: ④ 運転資本サイト（売掛金・買掛金）
...

Sheet 人員計画
A1: UNLID 人員計画（採用計画）v4.7 ─ 採用数・人件費がPL・感度分析に自動連動
A2: ★ この表の人件費合計・採用費合計が「前提条件」シートのSG&A（行31,32）に自動参照される
A4: ① 役職定義・単価テーブル（入力エリア）
A5: 役職 | B5: 月額給与(万円) | C5: 法定福利費率 | D5: 採用費単価(万円) | E5: 備考
A6: CEO / 創業者 | B6: 30 | C6: 0.15 | D6: 0 | E6: 役員報酬（Y1）、段階的引上げ
A7: FDE（フラクショナルFDE） | B7: 45 | C7: 0.15 | D7: 140 | E7: 正社員化。副業→内部登用でコスト圧縮
A8: CSM（カスタマーサクセス） | B8: 40 | C8: 0.15 | D8: 100 | E8: 1名が25〜30社を担当
A9: PM（プロジェクトMgr） | B9: 50 | C9: 0.15 | D9: 150 | E9: プロジェクト5件/人目安
A10: AIエンジニア | B10: 60 | C10: 0.15 | D10: 200 | E10: 自社ツール・大型PJ担当
A11: Admin / BizDev | B11: 35 | C11: 0.15 | D11: 80 | E11: バックオフィス・採用支援
A13: ② 採用スケジュール（期末時点ヘッドカウント）
A14: 役職 | B14: Y1期首 | C14: Y1採用 | D14: Y1期末 | E14: Y2採用 | F14: Y2期末 | G14: Y3採用 | H14: Y3期末
A15: CEO / 創業者 | B15: 1 | C15: 0 | D15: 1 | E15: 0 | F15: 1 | G15: 0 | H15: 1
A16: FDE（フラクショナルFDE） | B16: 0 | C16: 2 | D16: 2 | E16: 8 | F16: 10 | G16: 22 | H16: 32
A17: CSM（カスタマーサクセス） | B17: 0 | C17: 0 | D17: 0 | E17: 3 | F17: 3 | G17: 5 | H17: 8
A18: PM（プロジェクトMgr） | B18: 0 | C18: 0 | D18: 0 | E18: 2 | F18: 2 | G18: 4 | H18: 6
A19: AIエンジニア | B19: 0 | C19: 1 | D19: 1 | E19: 3 | F19: 4 | G19: 5 | H19: 9
A20: Admin / BizDev | B20: 0 | C20: 0 | D20: 0 | E20: 1 | F20: 1 | G20: 2 | H20: 3
A21: 合計（人） | B21: =SUM(B15:B20) | C21: =SUM(C15:C20) | D21: =SUM(D15:D20) | E21: =SUM(E15:E20) | F21: =SUM(F15:F20) | G21: =SUM(G15:G20) | H21: =SUM(H15:H20)
A24: ③ 年次人件費・採用費サマリー（→前提条件シートに自動連動）
A25: 役職 | B25: 月額給与(万) | C25: 法定福利率 | D25: Y1人件費 | E25: Y2人件費 | F25: Y3人件費
A26: CEO / 創業者 | B26: 30 | C26: 0.15 | D26: 414 | E26: 414 | F26: 414
A27: FDE（フラクショナルFDE） | B27: 45 | C27: 0.15 | D27: 1242 | E27: 6210 | F27: 19872
A28: CSM（カスタマーサクセス） | B28: 40 | C28: 0.15 | D28: 0 | E28: 1656 | F28: 4416
A29: PM（プロジェクトMgr） | B29: 50 | C29: 0.15 | D29: 0 | E29: 1380 | F29: 4140
A30: AIエンジニア | B30: 60 | C30: 0.15 | D30: 828 | E30: 3312 | F30: 7452
A31: Admin / BizDev | B31: 35 | C31: 0.15 | D31: 0 | E31: 483 | F31: 1449
A32: 人件費合計（万円） | D32: =SUM(D26:D31) | E32: =SUM(E26:E31) | F32: =SUM(F26:F31)
A34: ④ 採用費サマリー（採用人数 × 採用費単価）
A35: 役職 | B35: 採用費単価(万) | D35: Y1採用費 | E35: Y2採用費 | F35: Y3採用費
A36: CEO / 創業者 | B36: 0 | D36: 0 | E36: 0 | F36: 0
A37: FDE（フラクショナルFDE） | B37: 140 | D37: 280 | E37: 1120 | F37: 3080
A38: CSM（カスタマーサクセス） | B38: 100 | D38: 0 | E38: 300 | F38: 500
A39: PM（プロジェクトMgr） | B39: 150 | D39: 0 | E39: 300 | F39: 600
A40: AIエンジニア | B40: 200 | D40: 200 | E40: 600 | F40: 1000
A41: Admin / BizDev | B41: 80 | D41: 0 | E41: 80 | F41: 160
A42: 採用費合計（万円） | D42: =SUM(D36:D41) | E42: =SUM(E36:E41) | F42: =SUM(F36:F41)
A43: ★ 前提条件シート参照セル: 人件費=D32〜F32 / 採用費=D42〜F42
A45: ★ オンボーディング前提（v4.5 融資審査対応追記）
A46: 【研修期間設定】FDE・CSM・PMは入社後2ヶ月を研修期間とし、SME担当アサインは入社3ヶ月目以降。【コスト先行設計】給与・採用費は採用月から即時計上。売上貢献は翌々月から（コスト先行・売上後続の保守設計）。【モデル上の内包】B2B収益は「期中平均契約社数」ベースで計算しており、FDE稼働開始タイミングの遅れは「期中平均の保守性」に内包済み。月次CFで「コスト先行 / 売上後続」の構造は年÷12均等配分で反映されている。
...

Sheet PL（損益計算書）
A1: UNLID 損益計算書（P/L）v4.7 ─ 単位：万円 | 前提条件シート連動
A2: ★ v4.6: 売上合計(Row9)をPL独立SUM（B6+B7+B8）に変更。前提条件B15がPL!B9を参照する構造に変更済み（循環参照なし・整合性証明）。人件費・採用費は人員計画シートから自動参照。
A4: 項目 | B4: Year1 | C4: Year2 | D4: Year3 | E4: 3年累計
A5: ▌売上高
A6: B2B受託収益 | B6: =前提条件!B8 | C6: =前提条件!C8 | D6: =前提条件!D8 | E6: =B6+C6+D6
A7: 人材紹介フィー | B7: =前提条件!B11 | C7: =前提条件!C11 | D7: =前提条件!D11 | E7: =B7+C7+D7
A8: プロジェクト収益 | B8: =前提条件!B14 | C8: =前提条件!C14 | D8: =前提条件!D14 | E8: =B8+C8+D8
A9: 売上合計 | B9: =B6+B7+B8 | C9: =C6+C7+C8 | D9: =D6+D7+D8 | E9: =B9+C9+D9
A10: ▌売上原価（COGS）
A11: AIサーバー・API費 | B11: =前提条件!B20+前提条件!B21 | C11: =前提条件!C20+前提条件!C21 | D11: =前提条件!D20+前提条件!D21 | E11: =B11+C11+D11
A12: 副業ワーカー報酬 | B12: =前提条件!B23 | C12: =前提条件!C23 | D12: =前提条件!D23 | E12: =B12+C12+D12
A13: 外注エンジニア費 | B13: =前提条件!B24 | C13: =前提条件!C24 | D13: =前提条件!D24 | E13: =B13+C13+D13
A14: 売上原価合計 | B14: =前提条件!B25 | C14: =前提条件!C25 | D14: =前提条件!D25 | E14: =B14+C14+D14
A15: 売上総利益 | B15: =前提条件!B26 | C15: =前提条件!C26 | D15: =前提条件!D26 | E15: =B15+C15+D15
A16: 粗利率 | B16: =前提条件!B27 | C16: =前提条件!C27 | D16: =前提条件!D27
A17: ▌SG&A（販売費及び一般管理費）
A18: 人件費合計 | B18: =人員計画!D32 | C18: =人員計画!E32 | D18: =人員計画!F32 | E18: =B18+C18+D18
A19: 採用費合計 | B19: =人員計画!D42 | C19: =人員計画!E42 | D19: =人員計画!F42 | E19: =B19+C19+D19
A20: B2Bマーケ・CAC費 | B20: =前提条件!B33 | C20: =前提条件!C33 | D20: =前提条件!D33 | E20: =B20+C20+D20
A21: 人材紹介広告費 | B21: =前提条件!B34 | C21: =前提条件!C34 | D21: =前提条件!D34 | E21: =B21+C21+D21
A22: 地代家賃・オフィス | B22: =前提条件!B35 | C22: =前提条件!C35 | D22: =前提条件!D35 | E22: =B22+C22+D22
A23: SaaS・システム費 | B23: =前提条件!B36 | C23: =前提条件!C36 | D23: =前提条件!D36 | E23: =B23+C23+D23
A24: 法務・許認可費 | B24: =前提条件!B37 | C24: =前提条件!C37 | D24: =前提条件!D37 | E24: =B24+C24+D24
A25: その他固定費 | B25: =前提条件!B38 | C25: =前提条件!C38 | D25: =前提条件!D38 | E25: =B25+C25+D25
A26: SG&A合計 | B26: =前提条件!B39 | C26: =前提条件!C39 | D26: =前提条件!D39 | E26: =B26+C26+D26
A27: 営業利益 | B27: =前提条件!B40 | C27: =前提条件!C40 | D27: =前提条件!D40 | E27: =B27+C27+D27
A28: 営業利益率 | B28: =前提条件!B41 | C28: =前提条件!C41 | D28: =前提条件!D41
A29: 支払利息 | B29: =前提条件!B64 | C29: =前提条件!C64 | D29: =前提条件!D64 | E29: =B29+C29+D29
A30: 税引前利益 | B30: =前提条件!B65 | C30: =前提条件!C65 | D30: =前提条件!D65 | E30: =B30+C30+D30
A31: 法人税等（30%） | B31: =前提条件!B66 | C31: =前提条件!C66 | D31: =前提条件!D66 | E31: =B31+C31+D31
A32: 当期純利益 | B32: =前提条件!B67 | C32: =前提条件!C67 | D32: =前提条件!D67 | E32: =B32+C32+D32
A33: ▌参考指標
A34: 減価償却費（参考） | B34: =前提条件!B54 | C34: =前提条件!C54 | D34: =前提条件!D54 | E34: =B34+C34+D34
A35: EBITDA（参考） | B35: =前提条件!B40+前提条件!B54 | C35: =前提条件!C40+前提条件!C54 | D35: =前提条件!D40+前提条件!D54 | E35: =B35+C35+D35

Sheet BS（貸借対照表）
A1: UNLID 貸借対照表（B/S）v4.7 ─ 単位：万円 | 期末残高ベース
A2: 注：現金残高は「営業CF + 投資CF + 財務CF」の累積。貸借差額セル（Row28）で一致確認。
A4: 項目 | B4: Y0（期首） | C4: Y1末 | D4: Y2末 | E4: Y3末
A5: ▌流動資産
A6: 現金・預金 | B6: =前提条件!B59+前提条件!B62 | C6: =B6+前提条件!B67+前提条件!B54-前提条件!B52-前提条件!B47+前提条件!B48 | D6: =C6+前提条件!C67+前提条件!C54-前提条件!C52-(前提条件!C47-前提条件!B47)+(前提条件!C48-前提条件!B48)+前提条件!C60 | E6: =D6+前提条件!D67+前提条件!D54-前提条件!D52-(前提条件!D47-前提条件!C47)+(前提条件!D48-前提条件!C48)+前提条件!D61
A7: 売掛金 | B7: 0 | C7: =前提条件!B47 | D7: =前提条件!C47 | E7: =前提条件!D47
A8: 流動資産合計 | B8: =B6+B7 | C8: =C6+C7 | D8: =D6+D7 | E8: =E6+E7
A9: ▌固定資産
A10: ソフトウェア（純額） | B10: 0 | C10: =前提条件!B55 | D10: =前提条件!C55 | E10: =前提条件!D55
A11: 固定資産合計 | B11: =B10 | C11: =C10 | D11: =D10 | E11: =E10
A12: 資産合計 | B12: =B8+B11 | C12: =C8+C11 | D12: =D8+D11 | E12: =E8+E11
A14: ▌流動負債
A15: 買掛金 | B15: 0 | C15: =前提条件!B48 | D15: =前提条件!C48 | E15: =前提条件!D48
A16: 未払費用（人件費1ヶ月相当） | B16: 0 | C16: =ROUND(人員計画!D32/12,0) | D16: =ROUND(人員計画!E32/12,0) | E16: =ROUND(人員計画!F32/12,0)
A17: 流動負債合計 | B17: =B15+B16 | C17: =C15+C16 | D17: =D15+D16 | E17: =E15+E16
A18: ▌固定負債
A19: 借入金（期中返済なし想定） | B19: =前提条件!B62 | C19: =前提条件!B62 | D19: =前提条件!B62 | E19: =前提条件!B62
A20: 固定負債合計 | B20: =B19 | C20: =C19 | D20: =D19 | E20: =E19
A21: 負債合計 | B21: =B17+B20 | C21: =C17+C20 | D21: =D17+D20 | E21: =E17+E20
A23: ▌純資産
A24: 払込資本（資本金＋調達額累計） | B24: =前提条件!B59 | C24: =前提条件!B59 | D24: =前提条件!B59+前提条件!C60 | E24: =前提条件!B59+前提条件!C60+前提条件!D61
A25: 利益剰余金（累積純利益） | B25: 0 | C25: =前提条件!B67 | D25: =前提条件!B67+前提条件!C67 | E25: =前提条件!B67+前提条件!C67+前提条件!D67
A26: 純資産合計 | B26: =B24+B25 | C26: =C24+C25 | D26: =D24+D25 | E26: =E24+E25
A27: 負債・純資産合計（検証） | B27: =B21+B26 | C27: =C21+C26 | D27: =D21+D26 | E27: =E21+E26
A28: 貸借差額（0 = 正常・要確認） | B28: =B12-B27 | C28: =C12-C27 | D28: =D12-D27 | E28: =E12-E27

Sheet 月次CF（36ヶ月）
A1: UNLID 月次キャッシュフロー v4.7 ─ 単位：万円 | 36ヶ月展開
A2: ★ 月次値 = 年次値÷12（平均配分）。設備投資は各年度初月に一括計上。財務調達は固定月（M13/M25）に計上。 v4.4：銀行借入2,000万円に増額済み（前提条件B62）→ M1期首現金2,500万円
B3: Year 1 （M1〜M12） | N3: Year 2 （M13〜M24） | Z3: Year 3 （M25〜M36）
A4: 項目 / 月 | B4: M1 | C4: M2 | D4: M3 | E4: M4 | F4: M5 | G4: M6 | H4: M7 | I4: M8 | J4: M9 | K4: M10 | L4: M11 | M4: M12 | N4: M13 | O4: M14 | P4: M15 | Q4: M16 | R4: M17 | S4: M18 | T4: M19 | U4: M20 | V4: M21 | W4: M22 | X4: M23 | Y4: M24 | Z4: M25 | AA4: M26 | AB4: M27 | AC4: M28 | AD4: M29 | AE4: M30 | AF4: M31 | AG4: M32 | AH4: M33 | AI4: M34 | AJ4: M35 | AK4: M36
A5: ▌売上高
A6: B2B受託収益 | B6: =ROUND(前提条件!B8/12,0) | C6: =ROUND(前提条件!B8/12,0) | D6: =ROUND(前提条件!B8/12,0) | E6: =ROUND(前提条件!B8/12,0) | F6: =ROUND(前提条件!B8/12,0) | G6: =ROUND(前提条件!B8/12,0) | H6: =ROUND(前提条件!B8/12,0) | I6: =ROUND(前提条件!B8/12,0) | J6: =ROUND(前提条件!B8/12,0) | K6: =ROUND(前提条件!B8/12,0) | L6: =ROUND(前提条件!B8/12,0) | M6: =ROUND(前提条件!B8/12,0) | N6: =ROUND(前提条件!C8/12,0) | O6: =ROUND(前提条件!C8/12,0) | P6: =ROUND(前提条件!C8/12,0) | Q6: =ROUND(前提条件!C8/12,0) | R6: =ROUND(前提条件!C8/12,0) | S6: =ROUND(前提条件!C8/12,0) | T6: =ROUND(前提条件!C8/12,0) | U6: =ROUND(前提条件!C8/12,0) | V6: =ROUND(前提条件!C8/12,0) | W6: =ROUND(前提条件!C8/12,0) | X6: =ROUND(前提条件!C8/12,0) | Y6: =ROUND(前提条件!C8/12,0) | Z6: =ROUND(前提条件!D8/12,0) | AA6: =ROUND(前提条件!D8/12,0) | AB6: =ROUND(前提条件!D8/12,0) | AC6: =ROUND(前提条件!D8/12,0) | AD6: =ROUND(前提条件!D8/12,0) | AE6: =ROUND(前提条件!D8/12,0) | AF6: =ROUND(前提条件!D8/12,0) | AG6: =ROUND(前提条件!D8/12,0) | AH6: =ROUND(前提条件!D8/12,0) | AI6: =ROUND(前提条件!D8/12,0) | AJ6: =ROUND(前提条件!D8/12,0) | AK6: =ROUND(前提条件!D8/12,0)
A7: 人材紹介フィー | B7: =ROUND(前提条件!B11/12,0) | C7: =ROUND(前提条件!B11/12,0) | D7: =ROUND(前提条件!B11/12,0) | E7: =ROUND(前提条件!B11/12,0) | F7: =ROUND(前提条件!B11/12,0) | G7: =ROUND(前提条件!B11/12,0) | H7: =ROUND(前提条件!B11/12,0) | I7: =ROUND(前提条件!B11/12,0) | J7: =ROUND(前提条件!B11/12,0) | K7: =ROUND(前提条件!B11/12,0) | L7: =ROUND(前提条件!B11/12,0) | M7: =ROUND(前提条件!B11/12,0) | N7: =ROUND(前提条件!C11/12,0) | O7: =ROUND(前提条件!C11/12,0) | P7: =ROUND(前提条件!C11/12,0) | Q7: =ROUND(前提条件!C11/12,0) | R7: =ROUND(前提条件!C11/12,0) | S7: =ROUND(前提条件!C11/12,0) | T7: =ROUND(前提条件!C11/12,0) | U7: =ROUND(前提条件!C11/12,0) | V7: =ROUND(前提条件!C11/12,0) | W7: =ROUND(前提条件!C11/12,0) | X7: =ROUND(前提条件!C11/12,0) | Y7: =ROUND(前提条件!C11/12,0) | Z7: =ROUND(前提条件!D11/12,0) | AA7: =ROUND(前提条件!D11/12,0) | AB7: =ROUND(前提条件!D11/12,0) | AC7: =ROUND(前提条件!D11/12,0) | AD7: =ROUND(前提条件!D11/12,0) | AE7: =ROUND(前提条件!D11/12,0) | AF7: =ROUND(前提条件!D11/12,0) | AG7: =ROUND(前提条件!D11/12,0) | AH7: =ROUND(前提条件!D11/12,0) | AI7: =ROUND(前提条件!D11/12,0) | AJ7: =ROUND(前提条件!D11/12,0) | AK7: =ROUND(前提条件!D11/12,0)
A8: プロジェクト収益 | B8: =ROUND(前提条件!B14/12,0) | C8: =ROUND(前提条件!B14/12,0) | D8: =ROUND(前提条件!B14/12,0) | E8: =ROUND(前提条件!B14/12,0) | F8: =ROUND(前提条件!B14/12,0) | G8: =ROUND(前提条件!B14/12,0) | H8: =ROUND(前提条件!B14/12,0) | I8: =ROUND(前提条件!B14/12,0) | J8: =ROUND(前提条件!B14/12,0) | K8: =ROUND(前提条件!B14/12,0) | L8: =ROUND(前提条件!B14/12,0) | M8: =ROUND(前提条件!B14/12,0) | N8: =ROUND(前提条件!C14/12,0) | O8: =ROUND(前提条件!C14/12,0) | P8: =ROUND(前提条件!C14/12,0) | Q8: =ROUND(前提条件!C14/12,0) | R8: =ROUND(前提条件!C14/12,0) | S8: =ROUND(前提条件!C14/12,0) | T8: =ROUND(前提条件!C14/12,0) | U8: =ROUND(前提条件!C14/12,0) | V8: =ROUND(前提条件!C14/12,0) | W8: =ROUND(前提条件!C14/12,0) | X8: =ROUND(前提条件!C14/12,0) | Y8: =ROUND(前提条件!C14/12,0) | Z8: =ROUND(前提条件!D14/12,0) | AA8: =ROUND(前提条件!D14/12,0) | AB8: =ROUND(前提条件!D14/12,0) | AC8: =ROUND(前提条件!D14/12,0) | AD8: =ROUND(前提条件!D14/12,0) | AE8: =ROUND(前提条件!D14/12,0) | AF8: =ROUND(前提条件!D14/12,0) | AG8: =ROUND(前提条件!D14/12,0) | AH8: =ROUND(前提条件!D14/12,0) | AI8: =ROUND(前提条件!D14/12,0) | AJ8: =ROUND(前提条件!D14/12,0) | AK8: =ROUND(前提条件!D14/12,0)
A9: 売上合計 | B9: =ROUND(前提条件!B15/12,0) | C9: =ROUND(前提条件!B15/12,0) | D9: =ROUND(前提条件!B15/12,0) | E9: =ROUND(前提条件!B15/12,0) | F9: =ROUND(前提条件!B15/12,0) | G9: =ROUND(前提条件!B15/12,0) | H9: =ROUND(前提条件!B15/12,0) | I9: =ROUND(前提条件!B15/12,0) | J9: =ROUND(前提条件!B15/12,0) | K9: =ROUND(前提条件!B15/12,0) | L9: =ROUND(前提条件!B15/12,0) | M9: =ROUND(前提条件!B15/12,0) | N9: =ROUND(前提条件!C15/12,0) | O9: =ROUND(前提条件!C15/12,0) | P9: =ROUND(前提条件!C15/12,0) | Q9: =ROUND(前提条件!C15/12,0) | R9: =ROUND(前提条件!C15/12,0) | S9: =ROUND(前提条件!C15/12,0) | T9: =ROUND(前提条件!C15/12,0) | U9: =ROUND(前提条件!C15/12,0) | V9: =ROUND(前提条件!C15/12,0) | W9: =ROUND(前提条件!C15/12,0) | X9: =ROUND(前提条件!C15/12,0) | Y9: =ROUND(前提条件!C15/12,0) | Z9: =ROUND(前提条件!D15/12,0) | AA9: =ROUND(前提条件!D15/12,0) | AB9: =ROUND(前提条件!D15/12,0) | AC9: =ROUND(前提条件!D15/12,0) | AD9: =ROUND(前提条件!D15/12,0) | AE9: =ROUND(前提条件!D15/12,0) | AF9: =ROUND(前提条件!D15/12,0) | AG9: =ROUND(前提条件!D15/12,0) | AH9: =ROUND(前提条件!D15/12,0) | AI9: =ROUND(前提条件!D15/12,0) | AJ9: =ROUND(前提条件!D15/12,0) | AK9: =ROUND(前提条件!D15/12,0)
A10: ▌売上原価・粗利
A11: 売上原価合計 | B11: =ROUND(前提条件!B25/12,0) | C11: =ROUND(前提条件!B25/12,0) | D11: =ROUND(前提条件!B25/12,0) | E11: =ROUND(前提条件!B25/12,0) | F11: =ROUND(前提条件!B25/12,0) | G11: =ROUND(前提条件!B25/12,0) | H11: =ROUND(前提条件!B25/12,0) | I11: =ROUND(前提条件!B25/12,0) | J11: =ROUND(前提条件!B25/12,0) | K11: =ROUND(前提条件!B25/12,0) | L11: =ROUND(前提条件!B25/12,0) | M11: =ROUND(前提条件!B25/12,0) | N11: =ROUND(前提条件!C25/12,0) | O11: =ROUND(前提条件!C25/12,0) | P11: =ROUND(前提条件!C25/12,0) | Q11: =ROUND(前提条件!C25/12,0) | R11: =ROUND(前提条件!C25/12,0) | S11: =ROUND(前提条件!C25/12,0) | T11: =ROUND(前提条件!C25/12,0) | U11: =ROUND(前提条件!C25/12,0) | V11: =ROUND(前提条件!C25/12,0) | W11: =ROUND(前提条件!C25/12,0) | X11: =ROUND(前提条件!C25/12,0) | Y11: =ROUND(前提条件!C25/12,0) | Z11: =ROUND(前提条件!D25/12,0) | AA11: =ROUND(前提条件!D25/12,0) | AB11: =ROUND(前提条件!D25/12,0) | AC11: =ROUND(前提条件!D25/12,0) | AD11: =ROUND(前提条件!D25/12,0) | AE11: =ROUND(前提条件!D25/12,0) | AF11: =ROUND(前提条件!D25/12,0) | AG11: =ROUND(前提条件!D25/12,0) | AH11: =ROUND(前提条件!D25/12,0) | AI11: =ROUND(前提条件!D25/12,0) | AJ11: =ROUND(前提条件!D25/12,0) | AK11: =ROUND(前提条件!D25/12,0)
A12: 売上総利益 | B12: =ROUND(前提条件!B26/12,0) | C12: =ROUND(前提条件!B26/12,0) | D12: =ROUND(前提条件!B26/12,0) | E12: =ROUND(前提条件!B26/12,0) | F12: =ROUND(前提条件!B26/12,0) | G12: =ROUND(前提条件!B26/12,0) | H12: =ROUND(前提条件!B26/12,0) | I12: =ROUND(前提条件!B26/12,0) | J12: =ROUND(前提条件!B26/12,0) | K12: =ROUND(前提条件!B26/12,0) | L12: =ROUND(前提条件!B26/12,0) | M12: =ROUND(前提条件!B26/12,0) | N12: =ROUND(前提条件!C26/12,0) | O12: =ROUND(前提条件!C26/12,0) | P12: =ROUND(前提条件!C26/12,0) | Q12: =ROUND(前提条件!C26/12,0) | R12: =ROUND(前提条件!C26/12,0) | S12: =ROUND(前提条件!C26/12,0) | T12: =ROUND(前提条件!C26/12,0) | U12: =ROUND(前提条件!C26/12,0) | V12: =ROUND(前提条件!C26/12,0) | W12: =ROUND(前提条件!C26/12,0) | X12: =ROUND(前提条件!C26/12,0) | Y12: =ROUND(前提条件!C26/12,0) | Z12: =ROUND(前提条件!D26/12,0) | AA12: =ROUND(前提条件!D26/12,0) | AB12: =ROUND(前提条件!D26/12,0) | AC12: =ROUND(前提条件!D26/12,0) | AD12: =ROUND(前提条件!D26/12,0) | AE12: =ROUND(前提条件!D26/12,0) | AF12: =ROUND(前提条件!D26/12,0) | AG12: =ROUND(前提条件!D26/12,0) | AH12: =ROUND(前提条件!D26/12,0) | AI12: =ROUND(前提条件!D26/12,0) | AJ12: =ROUND(前提条件!D26/12,0) | AK12: =ROUND(前提条件!D26/12,0)
A13: ▌SG&A・営業利益
A14: SG&A合計 | B14: =ROUND(前提条件!B39/12,0) | C14: =ROUND(前提条件!B39/12,0) | D14: =ROUND(前提条件!B39/12,0) | E14: =ROUND(前提条件!B39/12,0) | F14: =ROUND(前提条件!B39/12,0) | G14: =ROUND(前提条件!B39/12,0) | H14: =ROUND(前提条件!B39/12,0) | I14: =ROUND(前提条件!B39/12,0) | J14: =ROUND(前提条件!B39/12,0) | K14: =ROUND(前提条件!B39/12,0) | L14: =ROUND(前提条件!B39/12,0) | M14: =ROUND(前提条件!B39/12,0) | N14: =ROUND(前提条件!C39/12,0) | O14: =ROUND(前提条件!C39/12,0) | P14: =ROUND(前提条件!C39/12,0) | Q14: =ROUND(前提条件!C39/12,0) | R14: =ROUND(前提条件!C39/12,0) | S14: =ROUND(前提条件!C39/12,0) | T14: =ROUND(前提条件!C39/12,0) | U14: =ROUND(前提条件!C39/12,0) | V14: =ROUND(前提条件!C39/12,0) | W14: =ROUND(前提条件!C39/12,0) | X14: =ROUND(前提条件!C39/12,0) | Y14: =ROUND(前提条件!C39/12,0) | Z14: =ROUND(前提条件!D39/12,0) | AA14: =ROUND(前提条件!D39/12,0) | AB14: =ROUND(前提条件!D39/12,0) | AC14: =ROUND(前提条件!D39/12,0) | AD14: =ROUND(前提条件!D39/12,0) | AE14: =ROUND(前提条件!D39/12,0) | AF14: =ROUND(前提条件!D39/12,0) | AG14: =ROUND(前提条件!D39/12,0) | AH14: =ROUND(前提条件!D39/12,0) | AI14: =ROUND(前提条件!D39/12,0) | AJ14: =ROUND(前提条件!D39/12,0) | AK14: =ROUND(前提条件!D39/12,0)
A15: 営業利益 | B15: =ROUND(前提条件!B40/12,0) | C15: =ROUND(前提条件!B40/12,0) | D15: =ROUND(前提条件!B40/12,0) | E15: =ROUND(前提条件!B40/12,0) | F15: =ROUND(前提条件!B40/12,0) | G15: =ROUND(前提条件!B40/12,0) | H15: =ROUND(前提条件!B40/12,0) | I15: =ROUND(前提条件!B40/12,0) | J15: =ROUND(前提条件!B40/12,0) | K15: =ROUND(前提条件!B40/12,0) | L15: =ROUND(前提条件!B40/12,0) | M15: =ROUND(前提条件!B40/12,0) | N15: =ROUND(前提条件!C40/12,0) | O15: =ROUND(前提条件!C40/12,0) | P15: =ROUND(前提条件!C40/12,0) | Q15: =ROUND(前提条件!C40/12,0) | R15: =ROUND(前提条件!C40/12,0) | S15: =ROUND(前提条件!C40/12,0) | T15: =ROUND(前提条件!C40/12,0) | U15: =ROUND(前提条件!C40/12,0) | V15: =ROUND(前提条件!C40/12,0) | W15: =ROUND(前提条件!C40/12,0) | X15: =ROUND(前提条件!C40/12,0) | Y15: =ROUND(前提条件!C40/12,0) | Z15: =ROUND(前提条件!D40/12,0) | AA15: =ROUND(前提条件!D40/12,0) | AB15: =ROUND(前提条件!D40/12,0) | AC15: =ROUND(前提条件!D40/12,0) | AD15: =ROUND(前提条件!D40/12,0) | AE15: =ROUND(前提条件!D40/12,0) | AF15: =ROUND(前提条件!D40/12,0) | AG15: =ROUND(前提条件!D40/12,0) | AH15: =ROUND(前提条件!D40/12,0) | AI15: =ROUND(前提条件!D40/12,0) | AJ15: =ROUND(前提条件!D40/12,0) | AK15: =ROUND(前提条件!D40/12,0)
A16: 当月純利益（税引後） | B16: =ROUND(前提条件!B67/12,0) | C16: =ROUND(前提条件!B67/12,0) | D16: =ROUND(前提条件!B67/12,0) | E16: =ROUND(前提条件!B67/12,0) | F16: =ROUND(前提条件!B67/12,0) | G16: =ROUND(前提条件!B67/12,0) | H16: =ROUND(前提条件!B67/12,0) | I16: =ROUND(前提条件!B67/12,0) | J16: =ROUND(前提条件!B67/12,0) | K16: =ROUND(前提条件!B67/12,0) | L16: =ROUND(前提条件!B67/12,0) | M16: =ROUND(前提条件!B67/12,0) | N16: =ROUND(前提条件!C67/12,0) | O16: =ROUND(前提条件!C67/12,0) | P16: =ROUND(前提条件!C67/12,0) | Q16: =ROUND(前提条件!C67/12,0) | R16: =ROUND(前提条件!C67/12,0) | S16: =ROUND(前提条件!C67/12,0) | T16: =ROUND(前提条件!C67/12,0) | U16: =ROUND(前提条件!C67/12,0) | V16: =ROUND(前提条件!C67/12,0) | W16: =ROUND(前提条件!C67/12,0) | X16: =ROUND(前提条件!C67/12,0) | Y16: =ROUND(前提条件!C67/12,0) | Z16: =ROUND(前提条件!D67/12,0) | AA16: =ROUND(前提条件!D67/12,0) | AB16: =ROUND(前提条件!D67/12,0) | AC16: =ROUND(前提条件!D67/12,0) | AD16: =ROUND(前提条件!D67/12,0) | AE16: =ROUND(前提条件!D67/12,0) | AF16: =ROUND(前提条件!D67/12,0) | AG16: =ROUND(前提条件!D67/12,0) | AH16: =ROUND(前提条件!D67/12,0) | AI16: =ROUND(前提条件!D67/12,0) | AJ16: =ROUND(前提条件!D67/12,0) | AK16: =ROUND(前提条件!D67/12,0)
A18: 当月償却費（参考・非現金） | B18: =ROUND(前提条件!B54/12,0) | C18: =ROUND(前提条件!B54/12,0) | D18: =ROUND(前提条件!B54/12,0) | E18: =ROUND(前提条件!B54/12,0) | F18: =ROUND(前提条件!B54/12,0) | G18: =ROUND(前提条件!B54/12,0) | H18: =ROUND(前提条件!B54/12,0) | I18: =ROUND(前提条件!B54/12,0) | J18: =ROUND(前提条件!B54/12,0) | K18: =ROUND(前提条件!B54/12,0) | L18: =ROUND(前提条件!B54/12,0) | M18: =ROUND(前提条件!B54/12,0) | N18: =ROUND(前提条件!C54/12,0) | O18: =ROUND(前提条件!C54/12,0) | P18: =ROUND(前提条件!C54/12,0) | Q18: =ROUND(前提条件!C54/12,0) | R18: =ROUND(前提条件!C54/12,0) | S18: =ROUND(前提条件!C54/12,0) | T18: =ROUND(前提条件!C54/12,0) | U18: =ROUND(前提条件!C54/12,0) | V18: =ROUND(前提条件!C54/12,0) | W18: =ROUND(前提条件!C54/12,0) | X18: =ROUND(前提条件!C54/12,0) | Y18: =ROUND(前提条件!C54/12,0) | Z18: =ROUND(前提条件!D54/12,0) | AA18: =ROUND(前提条件!D54/12,0) | AB18: =ROUND(前提条件!D54/12,0) | AC18: =ROUND(前提条件!D54/12,0) | AD18: =ROUND(前提条件!D54/12,0) | AE18: =ROUND(前提条件!D54/12,0) | AF18: =ROUND(前提条件!D54/12,0) | AG18: =ROUND(前提条件!D54/12,0) | AH18: =ROUND(前提条件!D54/12,0) | AI18: =ROUND(前提条件!D54/12,0) | AJ18: =ROUND(前提条件!D54/12,0) | AK18: =ROUND(前提条件!D54/12,0)
A19: ▌月次キャッシュフロー
A20: 期首現金残高 | B20: =BS（貸借対照表）!B6 | C20: =B26 | D20: =C26 | E20: =D26 | F20: =E26 | G20: =F26 | H20: =G26 | I20: =H26 | J20: =I26 | ... AK20: =AJ26
A21: 当月純利益 | B21: =ROUND(前提条件!B67/12,0) | C21: =ROUND(前提条件!B67/12,0) | D21: =ROUND(前提条件!B67/12,0) | E21: =ROUND(前提条件!B67/12,0) | F21: =ROUND(前提条件!B67/12,0) | G21: =ROUND(前提条件!B67/12,0) | H21: =ROUND(前提条件!B67/12,0) | I21: =ROUND(前提条件!B67/12,0) | J21: =ROUND(前提条件!B67/12,0) | K21: =ROUND(前提条件!B67/12,0) | L21: =ROUND(前提条件!B67/12,0) | M21: =ROUND(前提条件!B67/12,0) | N21: =ROUND(前提条件!C67/12,0) | O21: =ROUND(前提条件!C67/12,0) | P21: =ROUND(前提条件!C67/12,0) | Q21: =ROUND(前提条件!C67/12,0) | R21: =ROUND(前提条件!C67/12,0) | S21: =ROUND(前提条件!C67/12,0) | T21: =ROUND(前提条件!C67/12,0) | U21: =ROUND(前提条件!C67/12,0) | V21: =ROUND(前提条件!C67/12,0) | W21: =ROUND(前提条件!C67/12,0) | X21: =ROUND(前提条件!C67/12,0) | Y21: =ROUND(前提条件!C67/12,0) | Z21: =ROUND(前提条件!D67/12,0) | AA21: =ROUND(前提条件!D67/12,0) | AB21: =ROUND(前提条件!D67/12,0) | AC21: =ROUND(前提条件!D67/12,0) | AD21: =ROUND(前提条件!D67/12,0) | AE21: =ROUND(前提条件!D67/12,0) | AF21: =ROUND(前提条件!D67/12,0) | AG21: =ROUND(前提条件!D67/12,0) | AH21: =ROUND(前提条件!D67/12,0) | AI21: =ROUND(前提条件!D67/12,0) | AJ21: =ROUND(前提条件!D67/12,0) | AK21: =ROUND(前提条件!D67/12,0)
A22: 当月償却費（非現金加算） | B22: =ROUND(前提条件!B54/12,0) | C22: =ROUND(前提条件!B54/12,0) | D22: =ROUND(前提条件!B54/12,0) | E22: =ROUND(前提条件!B54/12,0) | F22: =ROUND(前提条件!B54/12,0) | G22: =ROUND(前提条件!B54/12,0) | H22: =ROUND(前提条件!B54/12,0) | I22: =ROUND(前提条件!B54/12,0) | J22: =ROUND(前提条件!B54/12,0) | K22: =ROUND(前提条件!B54/12,0) | L22: =ROUND(前提条件!B54/12,0) | M22: =ROUND(前提条件!B54/12,0) | N22: =ROUND(前提条件!C54/12,0) | O22: =ROUND(前提条件!C54/12,0) | P22: =ROUND(前提条件!C54/12,0) | Q22: =ROUND(前提条件!C54/12,0) | R22: =ROUND(前提条件!C54/12,0) | S22: =ROUND(前提条件!C54/12,0) | T22: =ROUND(前提条件!C54/12,0) | U22: =ROUND(前提条件!C54/12,0) | V22: =ROUND(前提条件!C54/12,0) | W22: =ROUND(前提条件!C54/12,0) | X22: =ROUND(前提条件!C54/12,0) | Y22: =ROUND(前提条件!C54/12,0) | Z22: =ROUND(前提条件!D54/12,0) | AA22: =ROUND(前提条件!D54/12,0) | AB22: =ROUND(前提条件!D54/12,0) | AC22: =ROUND(前提条件!D54/12,0) | AD22: =ROUND(前提条件!D54/12,0) | AE22: =ROUND(前提条件!D54/12,0) | AF22: =ROUND(前提条件!D54/12,0) | AG22: =ROUND(前提条件!D54/12,0) | AH22: =ROUND(前提条件!D54/12,0) | AI22: =ROUND(前提条件!D54/12,0) | AJ22: =ROUND(前提条件!D54/12,0) | AK22: =ROUND(前提条件!D54/12,0)
A23: 設備投資（－） | B23: =前提条件!B52 | C23: 0 | D23: 0 | E23: 0 | F23: 0 | G23: 0 | H23: 0 | I23: 0 | J23: 0 | K23: 0 | L23: 0 | M23: 0 | N23: =前提条件!C52 | O23: 0 | P23: 0 | Q23: 0 | R23: 0 | S23: 0 | T23: 0 | U23: 0 | V23: 0 | W23: 0 | X23: 0 | Y23: 0 | Z23: =前提条件!D52 | AA23: 0 | AB23: 0 | AC23: 0 | AD23: 0 | AE23: 0 | AF23: 0 | AG23: 0 | AH23: 0 | AI23: 0 | AJ23: 0 | AK23: 0
A24: 運転資本変動（ΔAR−ΔAP） | B24: =ROUND(前提条件!B47/12,0)-ROUND(前提条件!B48/12,0) | C24: =ROUND(前提条件!B47/12,0)-ROUND(前提条件!B48/12,0) | D24: =ROUND(前提条件!B47/12,0)-ROUND(前提条件!B48/12,0) | E24: =ROUND(前提条件!B47/12,0)-ROUND(前提条件!B48/12,0) | F24: =ROUND(前提条件!B47/12,0)-ROUND(前提条件!B48/12,0) | G24: =ROUND(前提条件!B47/12,0)-ROUND(前提条件!B48/12,0) | H24: =ROUND(前提条件!B47/12,0)-ROUND(前提条件!B48/12,0) | I24: =ROUND(前提条件!B47/12,0)-ROUND(前提条件!B48/12,0) | J24: =ROUND(前提条件!B47/12,0)-ROUND(前提条件!B48/12,0) | K24: =ROUND(前提条件!B47/12,0)-ROUND(前提条件!B48/12,0) | L24: =ROUND(前提条件!B47/12,0)-ROUND(前提条件!B48/12,0) | M24: =ROUND(前提条件!B47/12,0)-ROUND(前提条件!B48/12,0) | N24: =ROUND((前提条件!C47-前提条件!B47)/12,0)-ROUND((前提条件!C48-前提条件!B48)/12,0) | O24: =ROUND((前提条件!C47-前提条件!B47)/12,0)-ROUND((前提条件!C48-前提条件!B48)/12,0) | P24: =ROUND((前提条件!C47-前提条件!B47)/12,0)-ROUND((前提条件!C48-前提条件!B48)/12,0) | Q24: =ROUND((前提条件!C47-前提条件!B47)/12,0)-ROUND((前提条件!C48-前提条件!B48)/12,0) | R24: =ROUND((前提条件!C47-前提条件!B47)/12,0)-ROUND((前提条件!C48-前提条件!B48)/12,0) | S24: =ROUND((前提条件!C47-前提条件!B47)/12,0)-ROUND((前提条件!C48-前提条件!B48)/12,0) | T24: =ROUND((前提条件!C47-前提条件!B47)/12,0)-ROUND((前提条件!C48-前提条件!B48)/12,0) | U24: =ROUND((前提条件!C47-前提条件!B47)/12,0)-ROUND((前提条件!C48-前提条件!B48)/12,0) | V24: =ROUND((前提条件!C47-前提条件!B47)/12,0)-ROUND((前提条件!C48-前提条件!B48)/12,0) | W24: =ROUND((前提条件!C47-前提条件!B47)/12,0)-ROUND((前提条件!C48-前提条件!B48)/12,0) | X24: =ROUND((前提条件!C47-前提条件!B47)/12,0)-ROUND((前提条件!C48-前提条件!B48)/12,0) | Y24: =ROUND((前提条件!C47-前提条件!B47)/12,0)-ROUND((前提条件!C48-前提条件!B48)/12,0) | Z24: =ROUND((前提条件!D47-前提条件!C47)/12,0)-ROUND((前提条件!D48-前提条件!C48)/12,0) | AA24: =ROUND((前提条件!D47-前提条件!C47)/12,0)-ROUND((前提条件!D48-前提条件!C48)/12,0) | AB24: =ROUND((前提条件!D47-前提条件!C47)/12,0)-ROUND((前提条件!D48-前提条件!C48)/12,0) | AC24: =ROUND((前提条件!D47-前提条件!C47)/12,0)-ROUND((前提条件!D48-前提条件!C48)/12,0) | AD24: =ROUND((前提条件!D47-前提条件!C47)/12,0)-ROUND((前提条件!D48-前提条件!C48)/12,0) | AE24: =ROUND((前提条件!D47-前提条件!C47)/12,0)-ROUND((前提条件!D48-前提条件!C48)/12,0) | AF24: =ROUND((前提条件!D47-前提条件!C47)/12,0)-ROUND((前提条件!D48-前提条件!C48)/12,0) | AG24: =ROUND((前提条件!D47-前提条件!C47)/12,0)-ROUND((前提条件!D48-前提条件!C48)/12,0) | AH24: =ROUND((前提条件!D47-前提条件!C47)/12,0)-ROUND((前提条件!D48-前提条件!C48)/12,0) | AI24: =ROUND((前提条件!D47-前提条件!C47)/12,0)-ROUND((前提条件!D48-前提条件!C48)/12,0) | AJ24: =ROUND((前提条件!D47-前提条件!C47)/12,0)-ROUND((前提条件!D48-前提条件!C48)/12,0) | AK24: =ROUND((前提条件!D47-前提条件!C47)/12,0)-ROUND((前提条件!D48-前提条件!C48)/12,0)
A25: 財務調達（調達・借入金） | B25: 0 | C25: 0 | D25: 0 | E25: 0 | F25: 0 | G25: 0 | H25: 0 | I25: 0 | J25: 0 | K25: 0 | L25: 0 | M25: 0 | N25: =前提条件!C60 | O25: 0 | P25: 0 | Q25: 0 | R25: 0 | S25: 0 | T25: 0 | U25: 0 | V25: 0 | W25: 0 | X25: 0 | Y25: 0 | Z25: =前提条件!D61 | AA25: 0 | AB25: 0 | AC25: 0 | AD25: 0 | AE25: 0 | AF25: 0 | AG25: 0 | AH25: 0 | AI25: 0 | AJ25: 0 | AK25: 0
A26: 期末現金残高 | B26: =B20+B21+B22-B23-B24+B25-B30 | C26: =C20+C21+C22-C23-C24+C25-C30 | D26: =D20+D21+D22-D23-D24+D25-D30 | E26: =E20+E21+E22-E23-E24+E25-E30 | F26: =F20+F21+F22-F23-F24+F25-F30 | G26: =G20+G21+G22-G23-G24+G25-G30 | H26: =H20+H21+H22-H23-H24+H25-H30 | I26: =I20+I21+I22-I23-I24+I25-I30 | ... AK26: =AK20+AK21+AK22-AK23-AK24+AK25-AK30
A27: ★ 最低現預金残高（M1〜M36 MIN・元金返済後） ─ ショート確認 | B27: =MIN(B26:AK26) | C27: ← Row26に元金返済を含む。Row31(税)は別途確認。
A28: 月次安全ライン（月商×2ヶ月・各年度連動・動的） | B28: =ROUND(前提条件!B15/6,0) | C28: =ROUND(前提条件!B15/6,0) | D28: =ROUND(前提条件!B15/6,0) | E28: =ROUND(前提条件!B15/6,0) | F28: =ROUND(前提条件!B15/6,0) | G28: =ROUND(前提条件!B15/6,0) | H28: =ROUND(前提条件!B15/6,0) | I28: =ROUND(前提条件!B15/6,0) | J28: =ROUND(前提条件!B15/6,0) | K28: =ROUND(前提条件!B15/6,0) | L28: =ROUND(前提条件!B15/6,0) | M28: =ROUND(前提条件!B15/6,0) | N28: =ROUND(前提条件!C15/6,0) | O28: =ROUND(前提条件!C15/6,0) | P28: =ROUND(前提条件!C15/6,0) | Q28: =ROUND(前提条件!C15/6,0) | R28: =ROUND(前提条件!C15/6,0) | S28: =ROUND(前提条件!C15/6,0) | T28: =ROUND(前提条件!C15/6,0) | U28: =ROUND(前提条件!C15/6,0) | V28: =ROUND(前提条件!C15/6,0) | W28: =ROUND(前提条件!C15/6,0) | X28: =ROUND(前提条件!C15/6,0) | Y28: =ROUND(前提条件!C15/6,0) | Z28: =ROUND(前提条件!D15/6,0) | AA28: =ROUND(前提条件!D15/6,0) | AB28: =ROUND(前提条件!D15/6,0) | AC28: =ROUND(前提条件!D15/6,0) | AD28: =ROUND(前提条件!D15/6,0) | AE28: =ROUND(前提条件!D15/6,0) | AF28: =ROUND(前提条件!D15/6,0) | AG28: =ROUND(前提条件!D15/6,0) | AH28: =ROUND(前提条件!D15/6,0) | AI28: =ROUND(前提条件!D15/6,0) | AJ28: =ROUND(前提条件!D15/6,0) | AK28: =ROUND(前提条件!D15/6,0)
A29: 月次Cash判定（✓安全 / △要確認 ─ 全月✓が融資額妥当の証明） | B29: =IF(B26>=B28,"✓","△") | C29: =IF(C26>=C28,"✓","△") | D29: =IF(D26>=D28,"✓","△") | E29: =IF(E26>=E28,"✓","△") | F29: =IF(F26>=F28,"✓","△") | G29: =IF(G26>=G28,"✓","△") | H29: =IF(H26>=H28,"✓","△") | I29: =IF(I26>=I28,"✓","△") | ... AK29: =IF(AK26>=AK28,"✓","△")
A30: 元金返済（据置M1-M12・M13〜均等60回・月33万円） | B30: 0 | C30: 0 | D30: 0 | E30: 0 | F30: 0 | G30: 0 | H30: 0 | I30: 0 | J30: 0 | K30: 0 | L30: 0 | M30: 0 | N30: =ROUND(前提条件!B62/60,0) | O30: =ROUND(前提条件!B62/60,0) | P30: =ROUND(前提条件!B62/60,0) | Q30: =ROUND(前提条件!B62/60,0) | R30: =ROUND(前提条件!B62/60,0) | S30: =ROUND(前提条件!B62/60,0) | T30: =ROUND(前提条件!B62/60,0) | U30: =ROUND(前提条件!B62/60,0) | V30: =ROUND(前提条件!B62/60,0) | W30: =ROUND(前提条件!B62/60,0) | X30: =ROUND(前提条件!B62/60,0) | Y30: =ROUND(前提条件!B62/60,0) | Z30: =ROUND(前提条件!B62/60,0) | AA30: =ROUND(前提条件!B62/60,0) | AB30: =ROUND(前提条件!B62/60,0) | AC30: =ROUND(前提条件!B62/60,0) | AD30: =ROUND(前提条件!B62/60,0) | AE30: =ROUND(前提条件!B62/60,0) | AF30: =ROUND(前提条件!B62/60,0) | AG30: =ROUND(前提条件!B62/60,0) | AH30: =ROUND(前提条件!B62/60,0) | AI30: =ROUND(前提条件!B62/60,0) | AJ30: =ROUND(前提条件!B62/60,0) | AK30: =ROUND(前提条件!B62/60,0)
A31: 参考: Y2法人税 一括支払タイミング（M26 = Y2決算2ヶ月後） ─ Row26には未反映。M26のRow26残高からこの額を追加減算して確認。 | B31: 0 | C31: 0 | D31: 0 | E31: 0 | F31: 0 | G31: 0 | H31: 0 | I31: 0 | J31: 0 | K31: 0 | L31: 0 | M31: 0 | N31: 0 | O31: 0 | P31: 0 | Q31: 0 | R31: 0 | S31: 0 | T31: 0 | U31: 0 | V31: 0 | W31: 0 | X31: 0 | Y31: 0 | Z31: 0 | AA31: =-前提条件!C66 | AB31: 0 | AC31: 0 | AD31: 0 | AE31: 0 | AF31: 0 | AG31: 0 | AH31: 0 | AI31: 0 | AJ31: 0 | AK31: 0

Sheet 感度分析
A1: UNLID 感度分析 v4.7 ─ ユニットエコノミクス × シナリオ比較
A2: ★ マトリックスは静的計算。シナリオサマリーは前提条件シート基準値に倍率を乗算。
A4: ▌月商マトリックス（万円/月） ─ 単価：20万円/社 固定
A5: FDE人数 ╲ 担当社数 | B5: 4社 | C5: 5社 | D5: 6社 ★BEP | E5: 7社 | F5: 8社
A6: FDE 1名 | B6: 80 | C6: 100 | D6: 120 | E6: 140 | F6: 160
A7: FDE 2名 | B7: 160 | C7: 200 | D7: 240 | E7: 280 | F7: 320
A8: FDE 3名 | B8: 240 | C8: 300 | D8: 360 | E8: 420 | F8: 480
A9: FDE 4名 | B9: 320 | C9: 400 | D9: 480 | E9: 560 | F9: 640
A10: FDE 5名 | B10: 400 | C10: 500 | D10: 600 | E10: 700 | F10: 800
A12: ▌粗利マトリックス（万円/月） ─ ワーカー費15%控除 + FDE給与40万/名控除
A13: FDE人数 ╲ 担当社数 | B13: 4社 | C13: 5社 | D13: 6社 ★BEP | E13: 7社 | F13: 8社
A14: FDE 1名 | B14: 28 | C14: 45 | D14: 62 | E14: 79 | F14: 96
A15: FDE 2名 | B15: 56 | C15: 90 | D15: 124 | E15: 158 | F15: 192
A16: FDE 3名 | B16: 84 | C16: 135 | D16: 186 | E16: 237 | F16: 288
A17: FDE 4名 | B17: 112 | C17: 180 | D17: 248 | E17: 316 | F17: 384
A18: FDE 5名 | B18: 140 | C18: 225 | D18: 310 | E18: 395 | F18: 480
A20: ▌B2B単価感度（Year1） ─ FDE×社数構成不変、月額単価のみ変動
A21: 月額単価 | B21: Y1 売上（万円） | C21: Y1 粗利（万円） | D21: Y1 営業利益（万円） | E21: Base比変化率
A22: 15万円/社 | B22: =ROUND(前提条件!B15*0.75,0) | C22: =ROUND(前提条件!B26*0.75,0) | D22: =ROUND(前提条件!B40*0.75,0) | E22: -0.25
A23: 17万円/社 | B23: =ROUND(前提条件!B15*0.85,0) | C23: =ROUND(前提条件!B26*0.85,0) | D23: =ROUND(前提条件!B40*0.85,0) | E23: -0.15
A24: 20万円/社 ★Base | B24: =ROUND(前提条件!B15*1.0,0) | C24: =ROUND(前提条件!B26*1.0,0) | D24: =ROUND(前提条件!B40*1.0,0) | E24: 0
A25: 23万円/社 | B25: =ROUND(前提条件!B15*1.15,0) | C25: =ROUND(前提条件!B26*1.15,0) | D25: =ROUND(前提条件!B40*1.15,0) | E25: 0.15
A26: 25万円/社 | B26: =ROUND(前提条件!B15*1.25,0) | C26: =ROUND(前提条件!B26*1.25,0) | D26: =ROUND(前提条件!B40*1.25,0) | E26: 0.25
A28: ▌3シナリオサマリー（前提条件基準値 × 倍率）
A29: シナリオ | B29: Y1 売上 | C29: Y1 粗利 | D29: Y1 営業利益 | E29: Y2 売上 | F29: Y2 粗利 | G29: Y2 営業利益 | H29: Y3 売上 | I29: Y3 営業利益
A30: Bear（悲観） ×0.70 | B30: =ROUND(前提条件!B15*0.7,0) | C30: =ROUND(前提条件!B26*0.7,0) | D30: =ROUND(前提条件!B40*0.7,0) | E30: =ROUND(前提条件!C15*0.7,0) | F30: =ROUND(前提条件!C26*0.7,0) | G30: =ROUND(前提条件!C40*0.7,0) | H30: =ROUND(前提条件!D15*0.7,0) | I30: =ROUND(前提条件!D40*0.7,0)
A31: Base（中央） ×1.00 | B31: =ROUND(前提条件!B15*1.0,0) | C31: =ROUND(前提条件!B26*1.0,0) | D31: =ROUND(前提条件!B40*1.0,0) | E31: =ROUND(前提条件!C15*1.0,0) | F31: =ROUND(前提条件!C26*1.0,0) | G31: =ROUND(前提条件!C40*1.0,0) | H31: =ROUND(前提条件!D15*1.0,0) | I31: =ROUND(前提条件!D40*1.0,0)
A32: Bull（楽観） ×1.30 | B32: =ROUND(前提条件!B15*1.3,0) | C32: =ROUND(前提条件!B26*1.3,0) | D32: =ROUND(前提条件!B40*1.3,0) | E32: =ROUND(前提条件!C15*1.3,0) | F32: =ROUND(前提条件!C26*1.3,0) | G32: =ROUND(前提条件!C40*1.3,0) | H32: =ROUND(前提条件!D15*1.3,0) | I32: =ROUND(前提条件!D40*1.3,0)

Sheet SME単価市場調査
A1: UNLID SME市場単価調査——中小企業が払える金額・サービス別分析
A2: 調査時点：2024〜2026年 ／ 対象：従業員30〜300名の日本国内中小企業（SME） ／ 単位：万円（月額）
A4: ① 業務アウトソーシング・支援サービス 市場相場（SME向け）
A5: 業務カテゴリ | B5: 相場下限（万円/月） | C5: 相場上限（万円/月） | D5: 最多価格帯 | E5: UNLIDとの関係 | F5: 主要データ出典
A6: 経理・バックオフィスBPO | B6: 3 | C6: 15 | D6: 月5〜10万 | E6: UNLID若手が補完する領域 | F6: キャスター社公開料金(2025)・フジ子さん公式サイト(2025)
A7: 採用支援・HRコンサル | B7: 10 | C7: 25 | D7: 月15〜20万 | E7: UNLIDの競合＆補完領域 | F7: 帝国データバンク「HR関連支出調査」2024年
A8: IT・DX推進支援（週1顧問） | B8: 10 | C8: 30 | D8: 月15〜20万 | E8: UNLIDの直接競合価格帯 | F8: 中小企業庁「IT活用支援事業」公式資料2025年
A9: マーケティング・SNS代行 | B9: 10 | C9: 30 | D9: 月15〜25万 | E9: UNLIDクエストの一部として提供可 | F9: Web担当者Forum「外注マーケ費調査」2024年
A10: 外部CTO・技術顧問（週1〜2） | B10: 30 | C10: 60 | D10: 月40〜60万 | E10: UNLIDより高単価の上位市場 | F10: サーキュレーション・顧問名鑑 公開料金(2025)
A11: DXコンサル（大手系） | B11: 50 | C11: 200 | D11: 月80〜120万 | E11: UNLIDより5〜10倍高い。SMEは手が出ない | F11: 野村総研・アクセンチュア等提案書事例
A12: AI導入支援（スポット） | B12: 30 | C12: 150 | D12: プロジェクト型 | E12: UNLIDのプロジェクト型収益（3ヶ月80〜200万） | F12: 矢野経済研究所「AI導入コスト調査」2024年
A13: ★ UNLID フラクショナルFDE | B13: 20 | C13: 30 | D13: 月20〜30万 | E13: IT顧問より安く・ROI明確・最低単価20万円設定 | F13: 本資料 競合分析＆SME支払意欲調査
A15: ② SMEが月20〜30万円を払うことへのROI根拠（業務別）
A16: SMEの業務課題（痛み） | B16: UNLID対応クエスト | C16: 月額費用 | D16: 期待ROI（月） | E16: ROI根拠 | F16: データ出典
A17: 議事録・報告書・メール返信が多すぎて残業が止まらない | B17: AI出力仕上げ・資料整理代行（ワーカー） | C17: 月5〜15万 | D17: 月6〜10万の工数削減（30〜50h×時給2,000円） | E17: 残業削減＋担当者の高付加価値業務へのシフト | F17: リクルートワークス「業務効率化調査」2024・パーソル総研「働き方調査」2025
A18: 採用が決まらない・採用媒体費が高い | B18: 採用ブランディング記事・求人票AI強化（ワーカー担当） | C18: 月10〜20万 | D18: 採用媒体費50〜200万/年の削減効果 | E18: 採用ミスマッチ損失（年収×3倍相当）の回避 | F18: エン・ジャパン「中小企業採用コスト調査」2025年。採用1人あたり平均43万円
A19: AIを使えと言われるが何から始めていいかわからない | B19: FDEが業務整理→AI1つ選定→3ヶ月で成果事例化 | C19: 月20〜30万 | D19: DXコンサル（月50〜200万）の1/5〜1/10のコストで同等効果 | E19: IT投資対効果：中小企業白書2024（生産性20〜35%向上事例多数） | F19: 中小企業庁「2024年版中小企業白書」DX推進成功事例
A20: 問い合わせ対応に時間がかかりすぎる | B20: FAQ整理・チャットボット設定補助・対応マニュアルAI化 | C20: 月8〜15万 | D20: 対応工数30〜50%削減。担当者の本業集中 | E20: 1件あたり対応コスト2,500円×月200件×30%削減=月15万円相当 | F20: 矢野経済研究所「チャットボット市場」2024年。中小向け導入相場5〜30万/月
A21: 新入社員が育たない・先輩が育成に時間を割けない | B21: 新入社員ロープレ相手＋FBログ（ワーカーが対応） | C21: 月5〜15万 | D21: 離職防止効果。離職コスト（年収×1.5〜3倍）の回避 | E21: OJT崩壊データ：計画的OJT実施率40.9%→30.3%に低下（2025年） | F21: パーソル総合研究所「OJTに関する定量調査」2025年1月
A23: ③ 価格帯別 SME継続率・解約率仮説（業界ベンチマーク比較）
A24: 月額価格帯 | B24: 想定継続月数 | C24: 3ヶ月継続率 | D24: 12ヶ月継続率 | E24: 解約リスク要因 | F24: 参考：類似SaaSベンチマーク
A25: 月5〜10万（格安BPO） | B25: 平均3〜6ヶ月 | C25: 65〜75% | D25: 40〜55% | E25: ROIが見えにくい・担当者変更 | F25: Lancers等クラウドBPO実績
A26: 月10〜20万（中間価格帯） | B26: 平均6〜12ヶ月 | C26: 70〜80% | D26: 50〜65% | E26: 効果の可視化が鍵 | F26: HRコンサル・IT顧問業界ベンチマーク
A27: 月20〜30万（★UNLID価格帯） | B27: 平均12〜18ヶ月 | C27: 80〜88% | D27: 65〜75% | E27: ROI可視化と完遂ログが継続を後押し | F27: UNLIDベースライン仮説（3ヶ月でKPI達成設計）
A28: 月30〜60万（外部CTO相場） | B28: 平均12〜24ヶ月 | C28: 80〜90% | D28: 65〜75% | E28: 担当者変更・予算削減 | F28: サーキュレーション顧客定着率実績（参考）
A29: 【データ出典・注記】本シートのデータは公開資料・業界調査に基づく推計値（2024〜2026年）。詳細：中小企業庁「2024年版中小企業白書」/ 帝国データバンク各種産業調査 / パーソル総合研究所「OJT調査2025」/ リクルートワークス研究所 / 矢野経済研究所 / 各社公開料金表（キャスター・フジ子さん・サーキュレーション・顧問名鑑）
