Workbook

Sheet 前提条件
A1: UNLID 財務モデル 前提条件 v4.1
A2: 作成日：2026年3月 | 単位：万円 | 中央値シナリオ | 月額単価20〜30万円レンジ
A4: ① 売上ドライバー（各シートの売上数値の根拠）
A5: 項目 | B5: Year1 | C5: Year2 | D5: Year3
A6: B2B契約企業数（期末・社） | B6: 10 | C6: 50 | D6: 160
A7: FDE受託 月額単価（万円/社） | B7: 20 | C7: 23 | D7: 25
A8: B2B受託収益（万円） | B8: =B6*B7*12 | C8: =C6*C7*12 | D8: =D6*D7*12
A9: 人材紹介成立件数（件） | B9: 3 | C9: 20 | D9: 50
A10: 人材紹介フィー単価（万円/件） | B10: 140 | C10: 140 | D10: 140
A11: 人材紹介フィー合計（万円） | B11: =B9*B10 | C11: =C9*C10 | D11: =D9*D10
A12: 受託プロジェクト件数（件）※1 | B12: 0 | C12: 5 | D12: 15
A13: プロジェクト単価（万円/件）※2 | B13: 0 | C13: 160 | D13: 160
A14: プロジェクト収益（万円） | B14: =B12*B13 | C14: =C12*C13 | D14: =D12*D13
A15: 売上合計（万円） | B15: =B8+B11+B14 | C15: =C8+C11+C14 | D15: =D8+D11+D14
A16: ※1 プロジェクト件数：月額サブスクとは別の「成果物確定型・単発受託」件数（例：AI自動化システム構築 160万/件）
A17: ※2 プロジェクト単価：Year2以降 平均160万円想定（AI実装・業務自動化の3ヶ月プロジェクト相場）
A19: ② コストドライバー
A20: 項目 | B20: Year1 | C20: Year2 | D20: Year3
A21: FDE正社員数（人） | B21: 2 | C21: 10 | D21: 32
A22: FDE 月額人件費（万円/人） | B22: 45 | C22: 40 | D22: 42
A23: FDE人件費合計（万円） | B23: =B21*B22*12 | C23: =C21*C22*12 | D23: =D21*D22*12
A24: 創業者報酬（万円） | B24: 360 | C24: 600 | D24: 840
A25: 管理・営業スタッフ人件費（万円） | B25: 0 | C25: 1080 | D25: 3360
A26: 人件費合計（万円） | B26: =B23+B24+B25 | C26: =C23+C24+C25 | D26: =D23+D24+D25
A27: 副業ワーカー報酬率（対売上） | B27: 0.09 | C27: 0.08 | D27: 0.08
A28: 副業ワーカー報酬（万円） | B28: =前提条件!B15*B27 | C28: =前提条件!C15*C27 | D28: =前提条件!D15*D27
A29: オフィス・インフラ費（万円） | B29: 180 | C29: 360 | D29: 600
A30: マーケティング費（万円） | B30: 120 | C30: 360 | D30: 600
A31: 法務・許認可費（万円） | B31: 200 | C31: 300 | D31: 400
A32: 採用費（万円） | B32: 0 | C32: 500 | D32: 1500
A33: システム開発費（万円） | B33: 100 | C33: 300 | D33: 800
A34: その他（万円） | B34: 100 | C34: 200 | D34: 400
A36: ③ その他前提
A37: 項目 | B37: Year1 | C37: Year2 | D37: Year3
A38: 実効税率 | B38: 0.3 | C38: 0.3 | D38: 0.3
A39: 減価償却費（万円） | B39: 20 | C39: 80 | D39: 200
A40: 設備投資 Capex（万円） | B40: 100 | C40: 300 | D40: 800
A41: 初期調達資本（増資）（万円） | B41: 2000 | C41: 0 | D41: 0
A42: 売掛金 回転日数（日） | B42: 30 | C42: 30 | D42: 30
A43: 買掛金 回転日数（日） | B43: 15 | C43: 15 | D43: 15
...

Sheet PL（損益計算書）
A1: UNLID 損益計算書（P&L）3ヶ年
A2: 単位：万円 | 前提条件シートの数値と完全連動
A3: 項目 | B3: Year1 | C3: Year2 | D3: Year3 | E3: 3年累計
A4: 【売上高】
A5: B2B受託収益 | B5: =前提条件!B8 | C5: =前提条件!C8 | D5: =前提条件!D8 | E5: =SUM(B5:D5)
A6: 人材紹介フィー | B6: =前提条件!B11 | C6: =前提条件!C11 | D6: =前提条件!D11 | E6: =SUM(B6:D6)
A7: プロジェクト型受託 | B7: =前提条件!B14 | C7: =前提条件!C14 | D7: =前提条件!D14 | E7: =SUM(B7:D7)
A8: 売上合計 | B8: =SUM(B5:B7) | C8: =SUM(C5:C7) | D8: =SUM(D5:D7) | E8: =SUM(B8:D8)
A9: 前年比成長率 | B9: — | C9: =(C8-B8)/B8 | D9: =(D8-C8)/C8 | E9: —
A11: 【売上原価（変動費）】
A12: 副業ワーカー報酬 | B12: =前提条件!B28 | C12: =前提条件!C28 | D12: =前提条件!D28 | E12: =SUM(B12:D12)
A13: FDE業務委託費（外注） | B13: 0 | C13: 200 | D13: 600 | E13: =SUM(B13:D13)
A14: 売上原価合計 | B14: =SUM(B12:B13) | C14: =SUM(C12:C13) | D14: =SUM(D12:D13) | E14: =SUM(B14:D14)
A16: 売上総利益（粗利） | B16: =B8-B14 | C16: =C8-C14 | D16: =D8-D14 | E16: =SUM(B16:D16)
A17: 粗利率 | B17: =B16/B8 | C17: =C16/C8 | D17: =D16/D8
A19: 【販売費及び一般管理費（SGA）】
A20: FDE正社員 人件費 | B20: =前提条件!B23 | C20: =前提条件!C23 | D20: =前提条件!D23 | E20: =SUM(B20:D20)
A21: 創業者報酬 | B21: =前提条件!B24 | C21: =前提条件!C24 | D21: =前提条件!D24 | E21: =SUM(B21:D21)
A22: 管理・営業スタッフ人件費 | B22: =前提条件!B25 | C22: =前提条件!C25 | D22: =前提条件!D25 | E22: =SUM(B22:D22)
A23: 法定福利費（社会保険料 事業主負担） | B23: =前提条件!B45 | C23: =前提条件!C45 | D23: =前提条件!D45 | E23: =SUM(B23:D23)
A24: オフィス・インフラ費 | B24: =前提条件!B29 | C24: =前提条件!C29 | D24: =前提条件!D29 | E24: =SUM(B24:D24)
A25: マーケティング費 | B25: =前提条件!B30 | C25: =前提条件!C30 | D25: =前提条件!D30 | E25: =SUM(B25:D25)
A26: 法務・許認可費 | B26: =前提条件!B31 | C26: =前提条件!C31 | D26: =前提条件!D31 | E26: =SUM(B26:D26)
A27: 採用費 | B27: =前提条件!B32 | C27: =前提条件!C32 | D27: =前提条件!D32 | E27: =SUM(B27:D27)
A28: システム開発費 | B28: =前提条件!B33 | C28: =前提条件!C33 | D28: =前提条件!D33 | E28: =SUM(B28:D28)
A29: その他 | B29: =前提条件!B34 | C29: =前提条件!C34 | D29: =前提条件!D34 | E29: =SUM(B29:D29)
A30: 販管費合計 | B30: =SUM(B20:B29) | C30: =SUM(C20:C29) | D30: =SUM(D20:D29) | E30: =SUM(B30:D30)
A31: 販管費率 | B31: =B30/B8 | C31: =C30/C8 | D31: =D30/D8
A33: 営業利益（EBIT） | B33: =B16-B30 | C33: =C16-C30 | D33: =D16-D30 | E33: =SUM(B33:D33)
A34: 営業利益率 | B34: =B33/B8 | C34: =C33/C8 | D34: =D33/D8
A35: (+) 減価償却費（非資金費用 加算） | B35: =前提条件!B39 | C35: =前提条件!C39 | D35: =前提条件!D39
A36: EBITDA | B36: =B33+B35 | C36: =C33+C35 | D36: =D33+D35 | E36: =SUM(B36:D36)
A37: EBITDAマージン | B37: =B36/B8 | C37: =C36/C8 | D37: =D36/D8
A39: (-) 支払利息（政策公庫借入 年2.0%） | B39: =-前提条件!B54 | C39: =-前提条件!C54 | D39: =-前提条件!D54 | E39: =SUM(B39:D39)
A40: 税引前利益（EBT） | B40: =B33+B39 | C40: =C33+C39 | D40: =D33+D39 | E40: =SUM(B40:D40)
A41: 法人税等（実効税率30%）※EBTが正の場合のみ | B41: =IF(B40>0,ROUND(B40*前提条件!B38,0),0) | C41: =IF(C40>0,ROUND(C40*前提条件!B38,0),0) | D41: =IF(D40>0,ROUND(D40*前提条件!B38,0),0) | E41: =SUM(B41:D41)
A42: 当期純利益 | B42: =B40-B41 | C42: =C40-C41 | D42: =D40-D41 | E42: =SUM(B42:D42)
A43: 純利益率 | B43: =B42/B8 | C43: =C42/C8 | D43: =D42/D8

Sheet BS（貸借対照表）
A1: UNLID 貸借対照表（B/S）3ヶ年
A2: 単位：万円 | 期末残高 | PL・CF連動
A3: 項目 | B3: 期首（Year0） | C3: Year1末 | D3: Year2末 | E3: Year3末
A4: 【資産の部】
A5: 現金・預金 | B5: 2000 | C5: =B5+CF（キャッシュフロー計算書）!B24 | D5: =C5+CF（キャッシュフロー計算書）!C24 | E5: =D5+CF（キャッシュフロー計算書）!D24
A6: 売掛金 | B6: 0 | C6: =ROUND(PL（損益計算書）!B8*前提条件!B42/365,0) | D6: =ROUND(PL（損益計算書）!C8*前提条件!C42/365,0) | E6: =ROUND(PL（損益計算書）!D8*前提条件!D42/365,0)
A7: 前払費用・その他流動資産 | B7: 50 | C7: 50 | D7: 50 | E7: 50
A8: 流動資産合計 | B8: =SUM(B5:B7) | C8: =SUM(C5:C7) | D8: =SUM(D5:D7) | E8: =SUM(E5:E7)
A9: 固定資産（純額） | B9: 0 | C9: =B9+前提条件!B40-前提条件!B39 | D9: =C9+前提条件!C40-前提条件!C39 | E9: =D9+前提条件!D40-前提条件!D39
A10: 資産合計 | B10: =B8+B9 | C10: =C8+C9 | D10: =D8+D9 | E10: =E8+E9
A12: 【負債の部】
A13: 買掛金 | B13: 0 | C13: =ROUND(PL（損益計算書）!B14*前提条件!B43/365,0) | D13: =ROUND(PL（損益計算書）!C14*前提条件!C43/365,0) | E13: =ROUND(PL（損益計算書）!D14*前提条件!D43/365,0)
A14: 未払費用（1ヶ月分人件費等） | B14: 0 | C14: =ROUND(前提条件!B26/12,0) | D14: =ROUND(前提条件!C26/12,0) | E14: =ROUND(前提条件!D26/12,0)
A15: 流動負債合計 | B15: =SUM(B13:B14) | C15: =SUM(C13:C14) | D15: =SUM(D13:D14) | E15: =SUM(E13:E14)
A16: 政策公庫借入金（長期） | B16: 0 | C16: =ROUND(前提条件!B56,0) | D16: =ROUND(前提条件!C56,0) | E16: =ROUND(前提条件!D56,0)
A17: 負債合計 | B17: =B15+B16 | C17: =C15+C16 | D17: =D15+D16 | E17: =E15+E16
A19: 【純資産の部】
A20: 資本金・資本剰余金（累積増資） | B20: 2000 | C20: =B20+前提条件!B41 | D20: =C20+前提条件!C41 | E20: =D20+前提条件!D41
A21: 利益剰余金（累積） | B21: 0 | C21: =B21+PL（損益計算書）!B42 | D21: =C21+PL（損益計算書）!C42 | E21: =D21+PL（損益計算書）!D42
A22: 純資産合計 | B22: =B20+B21 | C22: =C20+C21 | D22: =D20+D21 | E22: =E20+E21
A23: 負債・純資産合計 | B23: =B17+B22 | C23: =C17+C22 | D23: =D17+D22 | E23: =E17+E22
A24: ✓ バランスチェック（資産合計−負債純資産合計 ＝ 0が正常） | B24: =B10-B23 | C24: =C10-C23 | D24: =D10-D23 | E24: =E10-E23

Sheet CF（キャッシュフロー計算書）
A1: UNLID キャッシュフロー計算書（間接法）3ヶ年
A2: 単位：万円 | PL・BS連動 ※CF合計＝期末現金変動額
A3: 項目 | B3: Year1 | C3: Year2 | D3: Year3 | E3: 3年累計
A4: 【営業活動によるCF】（間接法）
A5: 当期純利益（起点） | B5: =PL（損益計算書）!B42 | C5: =PL（損益計算書）!C42 | D5: =PL（損益計算書）!D42 | E5: =SUM(B5:D5)
A6: (+) 減価償却費（非資金費用） | B6: =前提条件!B39 | C6: =前提条件!C39 | D6: =前提条件!D39 | E6: =SUM(B6:D6)
A7: (-) 売掛金 増加 | B7: =-(BS（貸借対照表）!C6-BS（貸借対照表）!B6) | C7: =-(BS（貸借対照表）!D6-BS（貸借対照表）!C6) | D7: =-(BS（貸借対照表）!E6-BS（貸借対照表）!D6) | E7: =SUM(B7:D7)
A8: (+) 買掛金 増加 | B8: =BS（貸借対照表）!C13-BS（貸借対照表）!B13 | C8: =BS（貸借対照表）!D13-BS（貸借対照表）!C13 | D8: =BS（貸借対照表）!E13-BS（貸借対照表）!D13 | E8: =SUM(B8:D8)
A9: (+) 未払費用 増加 | B9: =BS（貸借対照表）!C14-BS（貸借対照表）!B14 | C9: =BS（貸借対照表）!D14-BS（貸借対照表）!C14 | D9: =BS（貸借対照表）!E14-BS（貸借対照表）!D14 | E9: =SUM(B9:D9)
A10: (-) 法人税等 支払い | B10: =-PL（損益計算書）!B41 | C10: =-PL（損益計算書）!C41 | D10: =-PL（損益計算書）!D41 | E10: =SUM(B10:D10)
A11: 営業活動CF 合計 | B11: =SUM(B5:B10) | C11: =SUM(C5:C10) | D11: =SUM(D5:D10) | E11: =SUM(B11:D11)
A13: 【投資活動によるCF】
A14: (-) 設備投資（Capex） | B14: =-前提条件!B40 | C14: =-前提条件!C40 | D14: =-前提条件!D40 | E14: =SUM(B14:D14)
A15: 投資活動CF 合計 | B15: =B14 | C15: =C14 | D15: =D14 | E15: =SUM(B15:D15)
A17: 【財務活動によるCF】
A18: (+) 増資・資本調達 | B18: =前提条件!B41 | C18: =前提条件!C41 | D18: =前提条件!D41 | E18: =SUM(B18:D18)
A19: (+) 政策公庫 借入金 新規調達 | B19: =前提条件!B50 | C19: =前提条件!C50 | D19: =前提条件!D50 | E19: =SUM(B19:D19)
A20: (-) 政策公庫 元本返済 | B20: =-ROUND(前提条件!B55,0) | C20: =-ROUND(前提条件!C55,0) | D20: =-ROUND(前提条件!D55,0) | E20: =SUM(B20:D20)
A21: (-) 支払利息（政策公庫 年2.0%） | B21: =-ROUND(前提条件!B54,0) | C21: =-ROUND(前提条件!C54,0) | D21: =-ROUND(前提条件!D54,0) | E21: =SUM(B21:D21)
A22: 財務活動CF 合計 | B22: =SUM(B18:B21) | C22: =SUM(C18:C21) | D22: =SUM(D18:D21) | E22: =SUM(B22:D22)
A24: 当期CF合計（純増減） | B24: =B11+B15+B22 | C24: =C11+C15+C22 | D24: =D11+D15+D22 | E24: =SUM(B24:D24)
A25: 期首現金残高 | B25: 2000 | C25: =B26 | D25: =C26 | E25: =B25
A26: 期末現金残高 | B26: =B25+B24 | C26: =C25+C24 | D26: =D25+D24 | E26: =D26
A27: ✓ BS現金との差異（0が正常） | B27: =B26-BS（貸借対照表）!C5 | C27: =C26-BS（貸借対照表）!D5 | D27: =D26-BS（貸借対照表）!E5

Sheet 感度分析
A1: UNLID 感度分析——2変数同時変動による営業利益・売上への影響
A2: 【読み方】各マスの数値は「2つの変数がその値のとき、ターゲット指標がいくらになるか」。黄色セル＝現状ベースライン付近。
A4: 【分析①】Year2 営業利益マトリクス：縦＝Year1→2の売上成長倍率 ／ 横＝原価率（売上比）
A5: Year1売上実績（万円） | B5: =PL（損益計算書）!B8 | D5: Year2 販管費固定額（万円） | E5: =PL（損益計算書）!C30
A6: → 各マス の 営業利益 ＝ Year1売上 × 成長倍率 × (1－原価率) － Year2販管費固定額
A8: 成長倍率 \ 原価率 | B8: 0.05 | C8: 0.07 | D8: 0.08 | E8: 0.09 | F8: 0.1 | G8: 0.12 | H8: 0.15
A9: 2.0x | B9: =$B$5*2.0*(1-B$8)-$E$5 | C9: =$B$5*2.0*(1-C$8)-$E$5 | D9: =$B$5*2.0*(1-D$8)-$E$5 | E9: =$B$5*2.0*(1-E$8)-$E$5 | F9: =$B$5*2.0*(1-F$8)-$E$5 | G9: =$B$5*2.0*(1-G$8)-$E$5 | H9: =$B$5*2.0*(1-H$8)-$E$5
A10: 3.0x | B10: =$B$5*3.0*(1-B$8)-$E$5 | C10: =$B$5*3.0*(1-C$8)-$E$5 | D10: =$B$5*3.0*(1-D$8)-$E$5 | E10: =$B$5*3.0*(1-E$8)-$E$5 | F10: =$B$5*3.0*(1-F$8)-$E$5 | G10: =$B$5*3.0*(1-G$8)-$E$5 | H10: =$B$5*3.0*(1-H$8)-$E$5
A11: 4.0x | B11: =$B$5*4.0*(1-B$8)-$E$5 | C11: =$B$5*4.0*(1-C$8)-$E$5 | D11: =$B$5*4.0*(1-D$8)-$E$5 | E11: =$B$5*4.0*(1-E$8)-$E$5 | F11: =$B$5*4.0*(1-F$8)-$E$5 | G11: =$B$5*4.0*(1-G$8)-$E$5 | H11: =$B$5*4.0*(1-H$8)-$E$5
A12: 5.0x | B12: =$B$5*5.0*(1-B$8)-$E$5 | C12: =$B$5*5.0*(1-C$8)-$E$5 | D12: =$B$5*5.0*(1-D$8)-$E$5 | E12: =$B$5*5.0*(1-E$8)-$E$5 | F12: =$B$5*5.0*(1-F$8)-$E$5 | G12: =$B$5*5.0*(1-G$8)-$E$5 | H12: =$B$5*5.0*(1-H$8)-$E$5
A13: 6.0x | B13: =$B$5*6.0*(1-B$8)-$E$5 | C13: =$B$5*6.0*(1-C$8)-$E$5 | D13: =$B$5*6.0*(1-D$8)-$E$5 | E13: =$B$5*6.0*(1-E$8)-$E$5 | F13: =$B$5*6.0*(1-F$8)-$E$5 | G13: =$B$5*6.0*(1-G$8)-$E$5 | H13: =$B$5*6.0*(1-H$8)-$E$5
A14: 7.0x | B14: =$B$5*7.0*(1-B$8)-$E$5 | C14: =$B$5*7.0*(1-C$8)-$E$5 | D14: =$B$5*7.0*(1-D$8)-$E$5 | E14: =$B$5*7.0*(1-E$8)-$E$5 | F14: =$B$5*7.0*(1-F$8)-$E$5 | G14: =$B$5*7.0*(1-G$8)-$E$5 | H14: =$B$5*7.0*(1-H$8)-$E$5
A15: 8.0x | B15: =$B$5*8.0*(1-B$8)-$E$5 | C15: =$B$5*8.0*(1-C$8)-$E$5 | D15: =$B$5*8.0*(1-D$8)-$E$5 | E15: =$B$5*8.0*(1-E$8)-$E$5 | F15: =$B$5*8.0*(1-F$8)-$E$5 | G15: =$B$5*8.0*(1-G$8)-$E$5 | H15: =$B$5*8.0*(1-H$8)-$E$5
A16: 10.0x | B16: =$B$5*10.0*(1-B$8)-$E$5 | C16: =$B$5*10.0*(1-C$8)-$E$5 | D16: =$B$5*10.0*(1-D$8)-$E$5 | E16: =$B$5*10.0*(1-E$8)-$E$5 | F16: =$B$5*10.0*(1-F$8)-$E$5 | G16: =$B$5*10.0*(1-G$8)-$E$5 | H16: =$B$5*10.0*(1-H$8)-$E$5
A18: ※ 現状ベース：成長倍率≒6x（Year1:2,820万→Year2:17,400万想定）、原価率≒8%（ワーカー報酬率）
A19: ※ 原価率が低いほど、かつ売上成長率が高いほど営業利益が大きくなる。赤字（負値）エリアは成長率が低く・原価率が高い左下ゾーン。
A22: 【分析②】Year2 売上マトリクス：縦＝B2B契約社数（社）／ 横＝FDE月額単価（万円/社）
A23: 人材紹介フィー（Year2固定）（万円） | B23: =PL（損益計算書）!C6 | D23: プロジェクト収益（Year2固定）（万円） | E23: =PL（損益計算書）!C7
A24: → 各マスの売上 ＝ 社数 × 月額単価 × 12 ＋ 人材紹介フィー ＋ プロジェクト収益
A26: 社数 \ 月額単価（万円） | B26: 15 | C26: 18 | D26: 20 | E26: 22 | F26: 23 | G26: 25 | H26: 28 | I26: 30
A27: 20 | B27: =20*15*12+$B$23+$E$23 | C27: =20*18*12+$B$23+$E$23 | D27: =20*20*12+$B$23+$E$23 | E27: =20*22*12+$B$23+$E$23 | F27: =20*23*12+$B$23+$E$23 | G27: =20*25*12+$B$23+$E$23 | H27: =20*28*12+$B$23+$E$23 | I27: =20*30*12+$B$23+$E$23
A28: 30 | B28: =30*15*12+$B$23+$E$23 | C28: =30*18*12+$B$23+$E$23 | D28: =30*20*12+$B$23+$E$23 | E28: =30*22*12+$B$23+$E$23 | F28: =30*23*12+$B$23+$E$23 | G28: =30*25*12+$B$23+$E$23 | H28: =30*28*12+$B$23+$E$23 | I28: =30*30*12+$B$23+$E$23
A29: 40 | B29: =40*15*12+$B$23+$E$23 | C29: =40*18*12+$B$23+$E$23 | D29: =40*20*12+$B$23+$E$23 | E29: =40*22*12+$B$23+$E$23 | F29: =40*23*12+$B$23+$E$23 | G29: =40*25*12+$B$23+$E$23 | H29: =40*28*12+$B$23+$E$23 | I29: =40*30*12+$B$23+$E$23
A30: 50 | B30: =50*15*12+$B$23+$E$23 | C30: =50*18*12+$B$23+$E$23 | D30: =50*20*12+$B$23+$E$23 | E30: =50*22*12+$B$23+$E$23 | F30: =50*23*12+$B$23+$E$23 | G30: =50*25*12+$B$23+$E$23 | H30: =50*28*12+$B$23+$E$23 | I30: =50*30*12+$B$23+$E$23
A31: 60 | B31: =60*15*12+$B$23+$E$23 | C31: =60*18*12+$B$23+$E$23 | D31: =60*20*12+$B$23+$E$23 | E31: =60*22*12+$B$23+$E$23 | F31: =60*23*12+$B$23+$E$23 | G31: =60*25*12+$B$23+$E$23 | H31: =60*28*12+$B$23+$E$23 | I31: =60*30*12+$B$23+$E$23
A32: 70 | B32: =70*15*12+$B$23+$E$23 | C32: =70*18*12+$B$23+$E$23 | D32: =70*20*12+$B$23+$E$23 | E32: =70*22*12+$B$23+$E$23 | F32: =70*23*12+$B$23+$E$23 | G32: =70*25*12+$B$23+$E$23 | H32: =70*28*12+$B$23+$E$23 | I32: =70*30*12+$B$23+$E$23
A33: 80 | B33: =80*15*12+$B$23+$E$23 | C33: =80*18*12+$B$23+$E$23 | D33: =80*20*12+$B$23+$E$23 | E33: =80*22*12+$B$23+$E$23 | F33: =80*23*12+$B$23+$E$23 | G33: =80*25*12+$B$23+$E$23 | H33: =80*28*12+$B$23+$E$23 | I33: =80*30*12+$B$23+$E$23
A34: ※ ★マス（50社×18万）がベースラインのYear2予測値。右上に行くほど売上が大きくなる。
A38: 【分析③】3シナリオ比較（楽観 / ベース / 保守）
A39: 3シナリオ説明：
A40: 楽観：B2B社数・月単価×1.3倍。保守：B2B社数0.7倍・月単価据置。ベース：前提条件シートの値。
A41: シナリオ | B41: Year1売上 | C41: Year1営業利益 | D41: Year2売上 | E41: Year2営業利益 | F41: Year3売上 | G41: Year3営業利益 | H41: 3年累計純利益
A42: 楽観（Upside） | B42: 3666 | C42: 810 | D42: 24360 | E42: 11050 | F42: 74620 | G42: 36000 | H42: 18900
A43: ベース（中央値） | B43: =PL（損益計算書）!B8 | C43: =PL（損益計算書）!B33 | D43: =PL（損益計算書）!C8 | E43: =PL（損益計算書）!C33 | F43: =PL（損益計算書）!D8 | G43: =PL（損益計算書）!D33 | H43: =PL（損益計算書）!E42
A44: 保守（Downside） | B44: 1974 | C44: -420 | D44: 8700 | E44: 1300 | F44: 31570 | G44: 8400 | H44: 4410
A50: 【分析④】FDE雇用形態別ユニットエコノミクス（1FDE×6社掛け持ち）
A51: FDE1名が6社（各月20万円）を担当した場合の粗利・採用費回収試算
A52: フェーズ | B52: FDE形態 | C52: 月商(6社) | D52: FDEコスト | E52: 月次粗利 | F52: 粗利率 | G52: 採用費 | H52: 採用費回収月数
A53: Ph0（創業者本人） | B53: 創業者＝FDE | C53: 120 | D53: 0 | E53: 120 | F53: 100.0% | G53: 0 | H53: 不要
A54: Ph1（副業FDE・業務委託） | B54: 業務委託（変動費） | C54: 120 | D54: 25 | E54: 95 | F54: 79.2% | G54: 0 | H54: 不要（業務委託）
...

Sheet SME単価市場調査
A1: UNLID SME市場単価調査——中小企業が払える金額・サービス別分析
A2: 調査時点：2024〜2026年 ／ 対象：従業員30〜300名の日本国内中小企業（SME） ／ 単位：万円（月額）
A4: ① 業務アウトソーシング・支援サービス 市場相場（SME向け）
A5: 業務カテゴリ | B5: 相場下限（万円/月） | C5: 相場上限（万円/月） | D5: 最多価格帯 | E5: UNLIDとの関係 | F5: 主要データ出典
A6: 経理・バックオフィスBPO | B6: 3 | C6: 15 | D6: 月5〜10万 | E6: UNLID若手が補完する領域 | F6: キャスター社公開料金(2025)・フジ子さん公式サイト(2025)
A7: 採用支援・HRコンサル | B7: 10 | C7: 25 | D7: 月15〜20万 | E7: UNLIDの競合＆補完領域 | F7: 帝国データバンク「HR関連支出調査」2024年
A8: IT・DX推進支援（週1顧問） | B8: 10 | C8: 30 | D8: 月15〜20万 | E8: UNLIDの直接競合価格帯 | F8: 中小企業庁「IT活用支援事業」公式資料2025年
A9: マーケティング・SNS代行 | B9: 10 | C9: 30 | D9: 月15〜25万 | E9: UNLIDクエストの一部として提供可 | F9: Web担当者Forum「外注マーケ費調査」2024年
A10: 外部CTO・技術顧問（週1〜2） | B10: 30 | C10: 60 | D10: 月40〜60万 | E10: UNLIDより高単価の上位市場 | F10: サーキュレーション・顧問名鑑 公開料金(2025)
A11: DXコンサル（大手系） | B11: 50 | C11: 200 | D11: 月80〜120万 | E11: UNLIDより5〜10倍高い。SMEは手が出ない | F11: 野村総研・アクセンチュア等提案書事例
A12: AI導入支援（スポット） | B12: 30 | C12: 150 | D12: プロジェクト型 | E12: UNLIDのプロジェクト型収益（3ヶ月80〜200万） | F12: 矢野経済研究所「AI導入コスト調査」2024年
A13: ★ UNLID フラクショナルFDE | B13: 20 | C13: 30 | D13: 月20〜30万 | E13: IT顧問より安く・ROI明確・最低単価20万円設定 | F13: 本資料 競合分析＆SME支払意欲調査
A15: ② SMEが月20〜30万円を払うことへのROI根拠（業務別）
A16: SMEの業務課題（痛み） | B16: UNLID対応クエスト | C16: 月額費用 | D16: 期待ROI（月） | E16: ROI根拠 | F16: データ出典
A17: 議事録・報告書・メール返信が多すぎて残業が止まらない | B17: AI出力仕上げ・資料整理代行（ワーカー） | C17: 月5〜15万 | D17: 月6〜10万の工数削減（30〜50h×時給2,000円） | E17: 残業削減＋担当者の高付加価値業務へのシフト | F17: リクルートワークス「業務効率化調査」2024・パーソル総研「働き方調査」2025
A18: 採用が決まらない・採用媒体費が高い | B18: 採用ブランディング記事・求人票AI強化（ワーカー担当） | C18: 月10〜20万 | D18: 採用媒体費50〜200万/年の削減効果 | E18: 採用ミスマッチ損失（年収×3倍相当）の回避 | F18: エン・ジャパン「中小企業採用コスト調査」2025年。採用1人あたり平均43万円
A19: AIを使えと言われるが何から始めていいかわからない | B19: FDEが業務整理→AI1つ選定→3ヶ月で成果事例化 | C19: 月20〜30万 | D19: DXコンサル（月50〜200万）の1/5〜1/10のコストで同等効果 | E19: IT投資対効果：中小企業白書2024（生産性20〜35%向上事例多数） | F19: 中小企業庁「2024年版中小企業白書」DX推進成功事例
A20: 問い合わせ対応に時間がかかりすぎる | B20: FAQ整理・チャットボット設定補助・対応マニュアルAI化 | C20: 月8〜15万 | D20: 対応工数30〜50%削減。担当者の本業集中 | E20: 1件あたり対応コスト2,500円×月200件×30%削減=月15万円相当 | F20: 矢野経済研究所「チャットボット市場」2024年。中小向け導入相場5〜30万/月
A21: 新入社員が育たない・先輩が育成に時間を割けない | B21: 新入社員ロープレ相手＋FBログ（ワーカーが対応） | C21: 月5〜15万 | D21: 離職防止効果。離職コスト（年収×1.5〜3倍）の回避 | E21: OJT崩壊データ：計画的OJT実施率40.9%→30.3%に低下（2025年） | F21: パーソル総合研究所「OJTに関する定量調査」2025年1月
A23: ③ 価格帯別 SME継続率・解約率仮説（業界ベンチマーク比較）
A24: 月額価格帯 | B24: 想定継続月数 | C24: 3ヶ月継続率 | D24: 12ヶ月継続率 | E24: 解約リスク要因 | F24: 参考：類似SaaSベンチマーク
A25: 月5〜10万（格安BPO） | B25: 平均3〜6ヶ月 | C25: 65〜75% | D25: 40〜55% | E25: ROIが見えにくい・担当者変更 | F25: Lancers等クラウドBPO実績
A26: 月10〜20万（中間価格帯） | B26: 平均6〜12ヶ月 | C26: 70〜80% | D26: 50〜65% | E26: 効果の可視化が鍵 | F26: HRコンサル・IT顧問業界ベンチマーク
A27: 月20〜30万（★UNLID価格帯） | B27: 平均12〜18ヶ月 | C27: 80〜88% | D27: 65〜75% | E27: ROI可視化と完遂ログが継続を後押し | F27: UNLIDベースライン仮説（3ヶ月でKPI達成設計）
A28: 月30〜60万（外部CTO相場） | B28: 平均12〜24ヶ月 | C28: 80〜90% | D28: 65〜75% | E28: 担当者変更・予算削減 | F28: サーキュレーション顧客定着率実績（参考）
A29: 【データ出典・注記】本シートのデータは公開資料・業界調査に基づく推計値（2024〜2026年）。詳細：中小企業庁「2024年版中小企業白書」/ 帝国データバンク各種産業調査 / パーソル総合研究所「OJT調査2025」/ リクルートワークス研究所 / 矢野経済研究所 / 各社公開料金表（キャスター・フジ子さん・サーキュレーション・顧問名鑑）
